INFO 2025-07-12 09:42:48,807 autoreload 1672 17208 Watching for file changes with StatReloader
INFO 2025-07-12 09:43:52,812 autoreload 21612 22700 Watching for file changes with StatReloader
INFO 2025-07-12 09:44:25,137 autoreload 10628 26448 Watching for file changes with StatReloader
INFO 2025-07-12 09:45:09,504 autoreload 10628 26448 C:\Users\sayhe\Downloads\stackit-mvp\stackit\settings.py changed, reloading.
INFO 2025-07-12 09:45:15,074 autoreload 9760 12660 Watching for file changes with StatReloader
INFO 2025-07-12 09:49:10,820 autoreload 19184 22544 Watching for file changes with StatReloader
INFO 2025-07-12 09:50:03,311 autoreload 19184 22544 C:\Users\sayhe\Downloads\stackit-mvp\stackit\settings.py changed, reloading.
INFO 2025-07-12 09:50:28,151 autoreload 31620 29372 Watching for file changes with StatReloader
INFO 2025-07-12 09:51:48,574 autoreload 31620 29372 C:\Users\sayhe\Downloads\stackit-mvp\apps\notifications\api\views.py changed, reloading.
INFO 2025-07-12 09:51:51,687 autoreload 30696 22040 Watching for file changes with StatReloader
INFO 2025-07-12 09:53:25,443 autoreload 30696 22040 C:\Users\sayhe\Downloads\stackit-mvp\apps\questions\admin.py changed, reloading.
INFO 2025-07-12 09:53:31,818 autoreload 25848 33484 Watching for file changes with StatReloader
ERROR 2025-07-12 09:53:36,971 log 25848 32124 Internal Server Error: /
Traceback (most recent call last):
  File "C:\Users\sayhe\AppData\Local\Programs\Python\Python311\Lib\site-packages\django\core\handlers\exception.py", line 55, in inner
    response = get_response(request)
               ^^^^^^^^^^^^^^^^^^^^^
  File "C:\Users\sayhe\AppData\Local\Programs\Python\Python311\Lib\site-packages\django\core\handlers\base.py", line 197, in _get_response
    response = wrapped_callback(request, *callback_args, **callback_kwargs)
               ^^^^^^^^^^^^^^^^^^^^^^^^^^^^^^^^^^^^^^^^^^^^^^^^^^^^^^^^^^^^
  File "C:\Users\sayhe\AppData\Local\Programs\Python\Python311\Lib\site-packages\django\views\generic\base.py", line 105, in view
    return self.dispatch(request, *args, **kwargs)
           ^^^^^^^^^^^^^^^^^^^^^^^^^^^^^^^^^^^^^^^
  File "C:\Users\sayhe\AppData\Local\Programs\Python\Python311\Lib\site-packages\django\views\generic\base.py", line 144, in dispatch
    return handler(request, *args, **kwargs)
           ^^^^^^^^^^^^^^^^^^^^^^^^^^^^^^^^^
  File "C:\Users\sayhe\AppData\Local\Programs\Python\Python311\Lib\site-packages\django\views\generic\list.py", line 158, in get
    self.object_list = self.get_queryset()
                       ^^^^^^^^^^^^^^^^^^^
  File "C:\Users\sayhe\Downloads\stackit-mvp\apps\core\views.py", line 20, in get_queryset
    ).annotate(
      ^^^^^^^^^
  File "C:\Users\sayhe\AppData\Local\Programs\Python\Python311\Lib\site-packages\django\db\models\query.py", line 1649, in annotate
    return self._annotate(args, kwargs, select=True)
           ^^^^^^^^^^^^^^^^^^^^^^^^^^^^^^^^^^^^^^^^^
  File "C:\Users\sayhe\AppData\Local\Programs\Python\Python311\Lib\site-packages\django\db\models\query.py", line 1694, in _annotate
    raise ValueError(
ValueError: The annotation 'answer_count' conflicts with a field on the model.
ERROR 2025-07-12 09:53:36,983 basehttp 25848 32124 "GET / HTTP/1.1" 500 95103
ERROR 2025-07-12 09:53:37,061 log 25848 19972 Internal Server Error: /
Traceback (most recent call last):
  File "C:\Users\sayhe\AppData\Local\Programs\Python\Python311\Lib\site-packages\django\core\handlers\exception.py", line 55, in inner
    response = get_response(request)
               ^^^^^^^^^^^^^^^^^^^^^
  File "C:\Users\sayhe\AppData\Local\Programs\Python\Python311\Lib\site-packages\django\core\handlers\base.py", line 197, in _get_response
    response = wrapped_callback(request, *callback_args, **callback_kwargs)
               ^^^^^^^^^^^^^^^^^^^^^^^^^^^^^^^^^^^^^^^^^^^^^^^^^^^^^^^^^^^^
  File "C:\Users\sayhe\AppData\Local\Programs\Python\Python311\Lib\site-packages\django\views\generic\base.py", line 105, in view
    return self.dispatch(request, *args, **kwargs)
           ^^^^^^^^^^^^^^^^^^^^^^^^^^^^^^^^^^^^^^^
  File "C:\Users\sayhe\AppData\Local\Programs\Python\Python311\Lib\site-packages\django\views\generic\base.py", line 144, in dispatch
    return handler(request, *args, **kwargs)
           ^^^^^^^^^^^^^^^^^^^^^^^^^^^^^^^^^
  File "C:\Users\sayhe\AppData\Local\Programs\Python\Python311\Lib\site-packages\django\views\generic\list.py", line 158, in get
    self.object_list = self.get_queryset()
                       ^^^^^^^^^^^^^^^^^^^
  File "C:\Users\sayhe\Downloads\stackit-mvp\apps\core\views.py", line 20, in get_queryset
    ).annotate(
      ^^^^^^^^^
  File "C:\Users\sayhe\AppData\Local\Programs\Python\Python311\Lib\site-packages\django\db\models\query.py", line 1649, in annotate
    return self._annotate(args, kwargs, select=True)
           ^^^^^^^^^^^^^^^^^^^^^^^^^^^^^^^^^^^^^^^^^
  File "C:\Users\sayhe\AppData\Local\Programs\Python\Python311\Lib\site-packages\django\db\models\query.py", line 1694, in _annotate
    raise ValueError(
ValueError: The annotation 'answer_count' conflicts with a field on the model.
ERROR 2025-07-12 09:53:37,069 basehttp 25848 19972 "GET / HTTP/1.1" 500 95103
ERROR 2025-07-12 09:53:48,711 log 25848 21692 Internal Server Error: /
Traceback (most recent call last):
  File "C:\Users\sayhe\AppData\Local\Programs\Python\Python311\Lib\site-packages\django\core\handlers\exception.py", line 55, in inner
    response = get_response(request)
               ^^^^^^^^^^^^^^^^^^^^^
  File "C:\Users\sayhe\AppData\Local\Programs\Python\Python311\Lib\site-packages\django\core\handlers\base.py", line 197, in _get_response
    response = wrapped_callback(request, *callback_args, **callback_kwargs)
               ^^^^^^^^^^^^^^^^^^^^^^^^^^^^^^^^^^^^^^^^^^^^^^^^^^^^^^^^^^^^
  File "C:\Users\sayhe\AppData\Local\Programs\Python\Python311\Lib\site-packages\django\views\generic\base.py", line 105, in view
    return self.dispatch(request, *args, **kwargs)
           ^^^^^^^^^^^^^^^^^^^^^^^^^^^^^^^^^^^^^^^
  File "C:\Users\sayhe\AppData\Local\Programs\Python\Python311\Lib\site-packages\django\views\generic\base.py", line 144, in dispatch
    return handler(request, *args, **kwargs)
           ^^^^^^^^^^^^^^^^^^^^^^^^^^^^^^^^^
  File "C:\Users\sayhe\AppData\Local\Programs\Python\Python311\Lib\site-packages\django\views\generic\list.py", line 158, in get
    self.object_list = self.get_queryset()
                       ^^^^^^^^^^^^^^^^^^^
  File "C:\Users\sayhe\Downloads\stackit-mvp\apps\core\views.py", line 20, in get_queryset
    ).annotate(
      ^^^^^^^^^
  File "C:\Users\sayhe\AppData\Local\Programs\Python\Python311\Lib\site-packages\django\db\models\query.py", line 1649, in annotate
    return self._annotate(args, kwargs, select=True)
           ^^^^^^^^^^^^^^^^^^^^^^^^^^^^^^^^^^^^^^^^^
  File "C:\Users\sayhe\AppData\Local\Programs\Python\Python311\Lib\site-packages\django\db\models\query.py", line 1694, in _annotate
    raise ValueError(
ValueError: The annotation 'answer_count' conflicts with a field on the model.
ERROR 2025-07-12 09:53:48,730 basehttp 25848 21692 "GET / HTTP/1.1" 500 94854
WARNING 2025-07-12 09:53:49,153 log 25848 21692 Not Found: /favicon.ico
WARNING 2025-07-12 09:53:49,155 basehttp 25848 21692 "GET /favicon.ico HTTP/1.1" 404 4113
INFO 2025-07-12 09:55:39,311 autoreload 25848 33484 C:\Users\sayhe\Downloads\stackit-mvp\apps\core\views.py changed, reloading.
INFO 2025-07-12 09:55:40,983 autoreload 11900 12728 Watching for file changes with StatReloader
ERROR 2025-07-12 09:56:47,220 log 11900 24360 Internal Server Error: /
Traceback (most recent call last):
  File "C:\Users\sayhe\AppData\Local\Programs\Python\Python311\Lib\site-packages\django\db\backends\utils.py", line 105, in _execute
    return self.cursor.execute(sql, params)
           ^^^^^^^^^^^^^^^^^^^^^^^^^^^^^^^^
  File "C:\Users\sayhe\AppData\Local\Programs\Python\Python311\Lib\site-packages\django\db\backends\sqlite3\base.py", line 360, in execute
    return super().execute(query, params)
           ^^^^^^^^^^^^^^^^^^^^^^^^^^^^^^
sqlite3.OperationalError: no such table: questions_question

The above exception was the direct cause of the following exception:

Traceback (most recent call last):
  File "C:\Users\sayhe\AppData\Local\Programs\Python\Python311\Lib\site-packages\django\core\handlers\exception.py", line 55, in inner
    response = get_response(request)
               ^^^^^^^^^^^^^^^^^^^^^
  File "C:\Users\sayhe\AppData\Local\Programs\Python\Python311\Lib\site-packages\django\core\handlers\base.py", line 197, in _get_response
    response = wrapped_callback(request, *callback_args, **callback_kwargs)
               ^^^^^^^^^^^^^^^^^^^^^^^^^^^^^^^^^^^^^^^^^^^^^^^^^^^^^^^^^^^^
  File "C:\Users\sayhe\AppData\Local\Programs\Python\Python311\Lib\site-packages\django\views\generic\base.py", line 105, in view
    return self.dispatch(request, *args, **kwargs)
           ^^^^^^^^^^^^^^^^^^^^^^^^^^^^^^^^^^^^^^^
  File "C:\Users\sayhe\AppData\Local\Programs\Python\Python311\Lib\site-packages\django\views\generic\base.py", line 144, in dispatch
    return handler(request, *args, **kwargs)
           ^^^^^^^^^^^^^^^^^^^^^^^^^^^^^^^^^
  File "C:\Users\sayhe\AppData\Local\Programs\Python\Python311\Lib\site-packages\django\views\generic\list.py", line 178, in get
    context = self.get_context_data()
              ^^^^^^^^^^^^^^^^^^^^^^^
  File "C:\Users\sayhe\Downloads\stackit-mvp\apps\core\views.py", line 27, in get_context_data
    context = super().get_context_data(**kwargs)
              ^^^^^^^^^^^^^^^^^^^^^^^^^^^^^^^^^^
  File "C:\Users\sayhe\AppData\Local\Programs\Python\Python311\Lib\site-packages\django\views\generic\list.py", line 128, in get_context_data
    paginator, page, queryset, is_paginated = self.paginate_queryset(
                                              ^^^^^^^^^^^^^^^^^^^^^^^
  File "C:\Users\sayhe\AppData\Local\Programs\Python\Python311\Lib\site-packages\django\views\generic\list.py", line 73, in paginate_queryset
    page = paginator.page(page_number)
           ^^^^^^^^^^^^^^^^^^^^^^^^^^^
  File "C:\Users\sayhe\AppData\Local\Programs\Python\Python311\Lib\site-packages\django\core\paginator.py", line 89, in page
    number = self.validate_number(number)
             ^^^^^^^^^^^^^^^^^^^^^^^^^^^^
  File "C:\Users\sayhe\AppData\Local\Programs\Python\Python311\Lib\site-packages\django\core\paginator.py", line 70, in validate_number
    if number > self.num_pages:
                ^^^^^^^^^^^^^^
  File "C:\Users\sayhe\AppData\Local\Programs\Python\Python311\Lib\site-packages\django\utils\functional.py", line 47, in __get__
    res = instance.__dict__[self.name] = self.func(instance)
                                         ^^^^^^^^^^^^^^^^^^^
  File "C:\Users\sayhe\AppData\Local\Programs\Python\Python311\Lib\site-packages\django\core\paginator.py", line 116, in num_pages
    if self.count == 0 and not self.allow_empty_first_page:
       ^^^^^^^^^^
  File "C:\Users\sayhe\AppData\Local\Programs\Python\Python311\Lib\site-packages\django\utils\functional.py", line 47, in __get__
    res = instance.__dict__[self.name] = self.func(instance)
                                         ^^^^^^^^^^^^^^^^^^^
  File "C:\Users\sayhe\AppData\Local\Programs\Python\Python311\Lib\site-packages\django\core\paginator.py", line 110, in count
    return c()
           ^^^
  File "C:\Users\sayhe\AppData\Local\Programs\Python\Python311\Lib\site-packages\django\db\models\query.py", line 604, in count
    return self.query.get_count(using=self.db)
           ^^^^^^^^^^^^^^^^^^^^^^^^^^^^^^^^^^^
  File "C:\Users\sayhe\AppData\Local\Programs\Python\Python311\Lib\site-packages\django\db\models\sql\query.py", line 644, in get_count
    return obj.get_aggregation(using, {"__count": Count("*")})["__count"]
           ^^^^^^^^^^^^^^^^^^^^^^^^^^^^^^^^^^^^^^^^^^^^^^^^^^^
  File "C:\Users\sayhe\AppData\Local\Programs\Python\Python311\Lib\site-packages\django\db\models\sql\query.py", line 626, in get_aggregation
    result = compiler.execute_sql(SINGLE)
             ^^^^^^^^^^^^^^^^^^^^^^^^^^^^
  File "C:\Users\sayhe\AppData\Local\Programs\Python\Python311\Lib\site-packages\django\db\models\sql\compiler.py", line 1623, in execute_sql
    cursor.execute(sql, params)
  File "C:\Users\sayhe\AppData\Local\Programs\Python\Python311\Lib\site-packages\django\db\backends\utils.py", line 122, in execute
    return super().execute(sql, params)
           ^^^^^^^^^^^^^^^^^^^^^^^^^^^^
  File "C:\Users\sayhe\AppData\Local\Programs\Python\Python311\Lib\site-packages\django\db\backends\utils.py", line 79, in execute
    return self._execute_with_wrappers(
           ^^^^^^^^^^^^^^^^^^^^^^^^^^^^
  File "C:\Users\sayhe\AppData\Local\Programs\Python\Python311\Lib\site-packages\django\db\backends\utils.py", line 92, in _execute_with_wrappers
    return executor(sql, params, many, context)
           ^^^^^^^^^^^^^^^^^^^^^^^^^^^^^^^^^^^^
  File "C:\Users\sayhe\AppData\Local\Programs\Python\Python311\Lib\site-packages\django\db\backends\utils.py", line 100, in _execute
    with self.db.wrap_database_errors:
  File "C:\Users\sayhe\AppData\Local\Programs\Python\Python311\Lib\site-packages\django\db\utils.py", line 91, in __exit__
    raise dj_exc_value.with_traceback(traceback) from exc_value
  File "C:\Users\sayhe\AppData\Local\Programs\Python\Python311\Lib\site-packages\django\db\backends\utils.py", line 105, in _execute
    return self.cursor.execute(sql, params)
           ^^^^^^^^^^^^^^^^^^^^^^^^^^^^^^^^
  File "C:\Users\sayhe\AppData\Local\Programs\Python\Python311\Lib\site-packages\django\db\backends\sqlite3\base.py", line 360, in execute
    return super().execute(query, params)
           ^^^^^^^^^^^^^^^^^^^^^^^^^^^^^^
django.db.utils.OperationalError: no such table: questions_question
ERROR 2025-07-12 09:56:47,234 basehttp 11900 24360 "GET / HTTP/1.1" 500 187215
INFO 2025-07-12 10:03:19,747 autoreload 11144 16160 Watching for file changes with StatReloader
INFO 2025-07-12 10:03:24,036 basehttp 11144 31020 "GET / HTTP/1.1" 200 8378
INFO 2025-07-12 10:03:24,984 basehttp 11144 29908 "GET /static/css/custom.css HTTP/1.1" 200 2802
WARNING 2025-07-12 10:03:25,841 log 11144 29908 Not Found: /favicon.ico
WARNING 2025-07-12 10:03:25,844 basehttp 11144 29908 "GET /favicon.ico HTTP/1.1" 404 4113
WARNING 2025-07-12 10:03:25,856 log 11144 4276 Not Found: /favicon.ico
WARNING 2025-07-12 10:03:25,857 basehttp 11144 4276 "GET /favicon.ico HTTP/1.1" 404 4113
WARNING 2025-07-12 10:03:25,876 log 11144 29908 Not Found: /favicon.ico
WARNING 2025-07-12 10:03:25,877 basehttp 11144 29908 "GET /favicon.ico HTTP/1.1" 404 4113
INFO 2025-07-12 10:03:37,924 basehttp 11144 23764 "GET / HTTP/1.1" 200 8378
INFO 2025-07-12 10:03:38,362 basehttp 11144 23764 "GET /static/css/custom.css HTTP/1.1" 200 2802
INFO 2025-07-12 10:03:41,886 basehttp 11144 23764 "GET /questions/ask/ HTTP/1.1" 302 0
INFO 2025-07-12 10:03:42,218 basehttp 11144 23764 "GET /accounts/login/?next=/questions/ask/ HTTP/1.1" 200 2360
INFO 2025-07-12 10:03:59,431 basehttp 11144 23764 "GET /questions/ask/ HTTP/1.1" 302 0
INFO 2025-07-12 10:03:59,446 basehttp 11144 23764 "GET /accounts/login/?next=/questions/ask/ HTTP/1.1" 200 2360
